<?xml version="1.0"?>
<robot name="robot" xmlns:xacro="http://www.ros.org/wiki/xacro">

	<xacro:include filename="$(find  nav)/urdf/materials.xacro" />
	<xacro:include filename="./robot_diff.gazebo" />

	<xacro:property name="side" value="left" />
	<xacro:macro name="wheel" side="left" x="0.25" y="0.4" z="1.0" />

  
	<!-- //////////////  ЛИНКИ //////////////////////-->
	<link name="base_link">

		<collision name='caster_collision'>
			<origin xyz="-0.15 0.0 -0.09" rpy="0.0 0.0 0.0" />
			<geometry>
				<sphere radius="0.01" />
			</geometry>
			<surface>
				<friction>
					<ode>
						<mu>0</mu> 
						<mu2>0</mu2>
						<slip1>1.0</slip1>
						<slip2>1.0</slip2>
					</ode>
				</friction>
			</surface>
		</collision>
		<visual name='caster_visual'>
			<origin xyz="-0.15 0.0 -0.09" rpy="0.0 0.0 0.0" />
			<geometry>
				<sphere radius="0.01" />
			</geometry>
			<material name="blue" />
		</visual>

		<collision name='caster_collision2'>
			<origin xyz="0.15 0.0 -0.09" rpy="0.0 0.0 0.0" />
			<geometry>
				<sphere radius="0.01" />
			</geometry>
			<surface>
				<friction>
					<ode>
						<mu>0</mu>
						<mu2>0</mu2>
						<slip1>1.0</slip1>
						<slip2>1.0</slip2>
					</ode>
				</friction>
			</surface>
		</collision>
		<visual name='caster_visual2'>
			<origin xyz="0.15 0.0 -0.09" rpy="0.0 0.0 0.0" />
			<geometry>
				<sphere radius="0.01" />
			</geometry>
			<material name="blue" />
		</visual>

		<origin xyz="0.0 0.0 0.0" rpy="0 0.0 0.0" />

		<visual name="base_visual">

			<geometry>
				<box size="0.2 0.2 0.1" />
			</geometry>

			<material name="blue" />

		</visual>


		<inertial>

			<mass value="10" />
			<inertia ixx="0.5" ixy="0" ixz="0" iyy="0.5" iyz="0" izz="0.5" />

		</inertial>

		<collision>

			<geometry>
				<box size="0.2 0.2 0.1" />
			</geometry>

		</collision>


	</link>

	<link name="wheel_left">
		<origin xyz="0.2 0 0" rpy=" 0 0 0" />
		<limit effort="100" velocity="100" />
		<joint_properties damping="0.1" friction="0.2" />
		<visual name="wheel_left_visual">

			<geometry>
				<cylinder length="0.05" radius="0.1" />
			</geometry>

			<material name="red" />

		</visual>

		<inertial>

			<mass value="1" />
			<inertia ixx="0.1" ixy="0" ixz="0" iyy="0.1" iyz="0" izz="0.1" />

		</inertial>

		<collision>

			<geometry>
				<cylinder length="0.05" radius="0.1" />
			</geometry>

		</collision>

	</link>

	<link name="wheel_right">

		<origin xyz="-2.2 0 0" rpy="0 1.57 0" />
		<limit effort="100" velocity="100" />
		<joint_properties damping="0.1" friction="0.2" />
		<visual name="wheel_left_visual">

			<geometry>

				<cylinder length="0.05" radius="0.1" />

			</geometry>

			<material name="white" />

		</visual>

		<inertial>

			<mass value="1" />
			<inertia ixx="0.1" ixy="0" ixz="0" iyy="0.1" iyz="0" izz="0.1" />

		</inertial>

		<collision>

			<geometry>
				<cylinder length="0.05" radius="0.1" />
			</geometry>

		</collision>

	</link>

	<link name="camera">
		<visual name="camera_visual">
			<origin xyz="0 0 0" rpy=" 0 0 0" />
			<geometry>
				<box size=".05 .05 .05" />
			</geometry>
			<material name="gray" />
		</visual>
	</link>

	<link name="lidar_link">
		<visual name="lidar_visual">
			<origin xyz="0 0 0" rpy=" 0 0 0" />
			<geometry>
				<cylinder length="0.05" radius="0.03" />
			</geometry>
			<material name="gray" />
		</visual>
	</link>


	<!-- //////////////  JOINTЫ //////////////////////-->
	<joint type="fixed" name="lidar_joint">
		<origin xyz="0 0 0.14" rpy="0 0 1.57" />
		<child link="lidar_link" />
		<parent link="base_link" />
	</joint>

	<joint type="fixed" name="camera_joint">
		<origin xyz="0.13 0 0.03" rpy="0 0 0" />
		<child link="camera" />
		<parent link="base_link" />
	</joint>

	<joint type="continuous" name="left_wheel_joint">

		<axis xyz="0 0 -1" />
		<origin xyz="0.0 0.15 0" rpy="1.57 0 0" />
		<child link="wheel_left" />
		<parent link="base_link" />

		<limit effort="10.0" velocity="10.0" />
		<joint_properties damping="1.0" friction="1.0"/>

	</joint>

	<joint type="continuous" name="right_wheel_joint">

		<axis xyz="0 0 -1" />
		<origin xyz="0.0 -0.15  0" rpy="1.57 0 0" />
		<child link="wheel_right" />
		<parent link="base_link" />

		<limit effort="10.0" velocity="10.0" />
		<joint_properties damping="1.0" friction="1.0"/>

	</joint>


	<!-- //////////////  ТРАНСМИССИИ?? //////////////////////-->
   <!-- <transmission name="tran1">
    <type>transmission_interface/SimpleTransmission</type>
    <joint name="left_wheel_joint">
        <hardwareInterface>EffortJointInterface</hardwareInterface>
    </joint>
    <actuator name="motor1">
        <hardwareInterface>EffortJointInterface</hardwareInterface>
        <mechanicalReduction>1</mechanicalReduction>
    </actuator>
  </transmission>
  
  <transmission name="tran2">
    <type>transmission_interface/SimpleTransmission</type>
    <joint name="right_wheel_joint">
        <hardwareInterface>EffortJointInterface</hardwareInterface>
    </joint>
    <actuator name="motor2">
        <hardwareInterface>EffortJointInterface</hardwareInterface>
        <mechanicalReduction>1</mechanicalReduction>
    </actuator>
  </transmission> -->


</robot> 