<?xml version="1.0" ?>
<!-- =================================================================================== -->
<!-- |    This document was autogenerated by xacro from robot_omni.xacro               | -->
<!-- |    EDITING THIS FILE BY HAND IS NOT RECOMMENDED                                 | -->
<!-- =================================================================================== -->
<robot name="mecanum">
  <gazebo>
    <plugin filename="libgazebo_ros_control.so" name="gazebo_ros_control">
      <robotNamespace>/omni_control</robotNamespace>
      <robotSimType>gazebo_ros_control/DefaultRobotHWSim</robotSimType>
    </plugin>
  </gazebo>
  <gazebo>
    <plugin filename="libmecanum.so" name="mecanum"/>
  </gazebo>
  <gazebo reference="base_link">
    <material>Gazebo/Orange</material>
  </gazebo>
  <gazebo reference="fl_link">
    <material>Gazebo/Gray</material>
  </gazebo>
  <gazebo reference="fr_link">
    <material>Gazebo/Gray</material>
  </gazebo>
  <gazebo reference="bl_link">
    <material>Gazebo/Gray</material>
  </gazebo>
  <gazebo reference="br_link">
    <material>Gazebo/Gray</material>
  </gazebo>
  <gazebo reference="range_front">
    <material>Gazebo/Green</material>
  </gazebo>
  <gazebo reference="range_left">
    <material>Gazebo/Green</material>
  </gazebo>
  <gazebo reference="range_right">
    <material>Gazebo/Green</material>
  </gazebo>
  <gazebo reference="range_rear">
    <material>Gazebo/Green</material>
  </gazebo>
  <gazebo reference="camera">
    <material>Gazebo/Black</material>
    <sensor name="camera1" type="camera">
      <update_rate>30.0</update_rate>
      <visualize>true</visualize>
      <camera name="head">
        <horizontal_fov>1.57</horizontal_fov>
        <image>
          <width>720</width>
          <height>480</height>
          <format>R8G8B8</format>
        </image>
        <clip>
          <near>0.02</near>
          <far>16</far>
        </clip>
      </camera>
      <plugin filename="libgazebo_ros_camera.so" name="camera_controller">
        <alwaysOn>true</alwaysOn>
        <updateRate>0.0</updateRate>
        <cameraName>head/camera1</cameraName>
        <imageTopicName>image_raw</imageTopicName>
        <cameraInfoTopicName>camera_info</cameraInfoTopicName>
        <frameName>camera</frameName>
        <hackBaseline>0.07</hackBaseline>
        <distortionK1>0.0</distortionK1>
        <distortionK2>0.0</distortionK2>
        <distortionK3>0.0</distortionK3>
        <distortionT1>0.0</distortionT1>
        <distortionT2>0.0</distortionT2>
      </plugin>
    </sensor>
  </gazebo>
  <gazebo reference="range_front">
    <sensor name="range_front" type="ray">
      <pose>0 0 0 0 0 0</pose>
      <update_rate>5</update_rate>
      <ray>
        <scan>
          <horizontal>
            <samples>5</samples>
            <resolution>1.0</resolution>
            <min_angle>-0.05</min_angle>
            <max_angle>0.05</max_angle>
          </horizontal>
          <vertical>
            <samples>5</samples>
            <resolution>1</resolution>
            <min_angle>-0.05</min_angle>
            <max_angle>0.05</max_angle>
          </vertical>
        </scan>
        <range>
          <min>0.01</min>
          <max>0.9</max>
          <resolution>0.01</resolution>
        </range>
      </ray>
      <plugin filename="libgazebo_ros_range.so" name="gazebo_ros_range">
        <gaussianNoise>0.005</gaussianNoise>
        <alwaysOn>true</alwaysOn>
        <updateRate>5</updateRate>
        <topicName>range/front</topicName>
        <frameName>range_front</frameName>
        <fov>0.1</fov>
        <radiation>ultrasound</radiation>
      </plugin>
    </sensor>
  </gazebo>
  <gazebo reference="range_left">
    <sensor name="range_left" type="ray">
      <pose>0 0 0 0 0 0</pose>
      <update_rate>5</update_rate>
      <ray>
        <scan>
          <horizontal>
            <samples>5</samples>
            <resolution>1.0</resolution>
            <min_angle>-0.05</min_angle>
            <max_angle>0.05</max_angle>
          </horizontal>
          <vertical>
            <samples>5</samples>
            <resolution>1</resolution>
            <min_angle>-0.05</min_angle>
            <max_angle>0.05</max_angle>
          </vertical>
        </scan>
        <range>
          <min>0.01</min>
          <max>0.9</max>
          <resolution>0.01</resolution>
        </range>
      </ray>
      <plugin filename="libgazebo_ros_range.so" name="gazebo_ros_range">
        <gaussianNoise>0.005</gaussianNoise>
        <alwaysOn>true</alwaysOn>
        <updateRate>5</updateRate>
        <topicName>range/left</topicName>
        <frameName>range_left</frameName>
        <fov>0.1</fov>
        <radiation>ultrasound</radiation>
      </plugin>
    </sensor>
  </gazebo>
  <gazebo reference="range_right">
    <sensor name="range_right" type="ray">
      <pose>0 0 0 0 0 0</pose>
      <update_rate>5</update_rate>
      <ray>
        <scan>
          <horizontal>
            <samples>5</samples>
            <resolution>1.0</resolution>
            <min_angle>-0.05</min_angle>
            <max_angle>0.05</max_angle>
          </horizontal>
          <vertical>
            <samples>5</samples>
            <resolution>1</resolution>
            <min_angle>-0.05</min_angle>
            <max_angle>0.05</max_angle>
          </vertical>
        </scan>
        <range>
          <min>0.01</min>
          <max>0.9</max>
          <resolution>0.01</resolution>
        </range>
      </ray>
      <plugin filename="libgazebo_ros_range.so" name="gazebo_ros_range">
        <gaussianNoise>0.005</gaussianNoise>
        <alwaysOn>true</alwaysOn>
        <updateRate>5</updateRate>
        <topicName>range/right</topicName>
        <frameName>range_right</frameName>
        <fov>0.1</fov>
        <radiation>ultrasound</radiation>
      </plugin>
    </sensor>
  </gazebo>
  <gazebo reference="range_rear">
    <sensor name="range_rear" type="ray">
      <pose>0 0 0 0 0 0</pose>
      <update_rate>5</update_rate>
      <ray>
        <scan>
          <horizontal>
            <samples>5</samples>
            <resolution>1.0</resolution>
            <min_angle>-0.05</min_angle>
            <max_angle>0.05</max_angle>
          </horizontal>
          <vertical>
            <samples>5</samples>
            <resolution>1</resolution>
            <min_angle>-0.05</min_angle>
            <max_angle>0.05</max_angle>
          </vertical>
        </scan>
        <range>
          <min>0.01</min>
          <max>0.9</max>
          <resolution>0.01</resolution>
        </range>
      </ray>
      <plugin filename="libgazebo_ros_range.so" name="gazebo_ros_range">
        <gaussianNoise>0.005</gaussianNoise>
        <alwaysOn>true</alwaysOn>
        <updateRate>5</updateRate>
        <topicName>range/rear</topicName>
        <frameName>range_rear</frameName>
        <fov>0.1</fov>
        <radiation>ultrasound</radiation>
      </plugin>
    </sensor>
  </gazebo>
  <material name="black">
    <color rgba="0.0 0.0 0.0 1.0"/>
  </material>
  <material name="blue">
    <color rgba="0.0 0.0 0.8 1.0"/>
  </material>
  <material name="green">
    <color rgba="0.11764705882352941 1.0 0.11764705882352941 1.0"/>
  </material>
  <material name="grey">
    <color rgba="0.2 0.2 0.2 1.0"/>
  </material>
  <material name="orange">
    <color rgba="1.0 0.4235294117647059 0.0392156862745098 1.0"/>
  </material>
  <material name="brown">
    <color rgba="0.8705882352941177 0.8117647058823529 0.7647058823529411 1.0"/>
  </material>
  <material name="red">
    <color rgba="0.8 0.0 0.0 1.0"/>
  </material>
  <material name="white">
    <color rgba="1.0 1.0 1.0 1.0"/>
  </material>
  <!--~~~~~~~~~~~~~~~~~~~~~~~~ ~ ROBOT BASE ~ ~~~~~~~~~~~~~~~~~~~~~~~~~~~~~~-->
  <link name="base_link">
    <collision>
      <origin rpy="0 0 0" xyz="0 0 0.0"/>
      <geometry>
        <box size="0.3683 0.3683 0.0635"/>
      </geometry>
    </collision>
    <visual>
      <origin rpy="0 0 0" xyz="0 0 0.0"/>
      <geometry>
        <box size="0.3683 0.3683 0.0635"/>
      </geometry>
      <material name="orange"/>
    </visual>
    <inertial>
      <mass value="3.1"/>
      <origin rpy="0 0 0" xyz="0 0 0"/>
      <inertia ixx="1e-1" ixy="0" ixz="0" iyy="1e-1" iyz="0" izz="1e-1"/>
    </inertial>
  </link>
  <link name="fl_link">
    <visual>
      <origin rpy="1.5707963267948966 0.0 0.0" xyz="0 0 0"/>
      <geometry>
        <cylinder length="0.0762" radius="0.1016"/>
        <!-- <mesh filename="package://nav/urdf/omniurdf/Left_wheel.stl" scale="0.0015 0.0015 0.0015"/> -->
      </geometry>
      <material name="white"/>
    </visual>
    <collision>
      <geometry>
        <cylinder length="0.0762" radius="0.1016"/>
      </geometry>
      <origin rpy="1.5707963267948966 0 0" xyz="0 0 0"/>
    </collision>
    <inertial>
      <mass value="0.01"/>
      <origin rpy="1.5707963267948966 0 0" xyz="0 0 0"/>
      <inertia ixx="1e-6" ixy="0" ixz="0" iyy="1e-6" iyz="0" izz="1e-6"/>
    </inertial>
  </link>
  <link name="fr_link">
    <visual>
      <origin rpy="1.5707963267948966 0 0" xyz="0 0 0"/>
      <geometry>
        <cylinder length="0.0762" radius="0.1016"/>
        <!-- <mesh filename="package://nav/urdf/omniurdf/Right_wheel.stl" scale="0.0015 0.0015 0.0015"/> -->
      </geometry>
      <material name="white"/>
    </visual>
    <collision>
      <geometry>
        <cylinder length="0.0762" radius="0.1016"/>
      </geometry>
      <origin rpy="1.5707963267948966 0 0" xyz="0 0 0"/>
    </collision>
    <inertial>
      <mass value="0.01"/>
      <origin rpy="1.5707963267948966 0 0" xyz="0 0 0"/>
      <inertia ixx="1e-6" ixy="0" ixz="0" iyy="1e-6" iyz="0" izz="1e-6"/>
    </inertial>
  </link>
  <link name="bl_link">
    <visual>
      <geometry>
        <cylinder length="0.0762" radius="0.1016"/>
        <!-- <mesh filename="package://nav/urdf/omniurdf/Right_wheel.stl" scale="0.0015 0.0015 0.0015"/> -->
      </geometry>
      <origin rpy="1.5707963267948966 0 0" xyz="0 0 0"/>
      <material name="white"/>
    </visual>
    <collision>
      <geometry>
        <cylinder length="0.0762" radius="0.1016"/>
      </geometry>
      <origin rpy="1.5707963267948966 0 0" xyz="0 0 0"/>
    </collision>
    <inertial>
      <mass value="0.01"/>
      <origin rpy="1.5707963267948966 0 0" xyz="0 0 0"/>
      <inertia ixx="1e-6" ixy="0" ixz="0" iyy="1e-6" iyz="0" izz="1e-6"/>
    </inertial>
  </link>
  <link name="br_link">
    <visual>
      <origin rpy="1.5707963267948966 0 0" xyz="0 0 0"/>
      <geometry>
        <cylinder length="0.0762" radius="0.1016"/>
        <!-- <mesh filename="package://nav/urdf/omniurdf/Left_wheel.stl" scale="0.0015 0.0015 0.0015"/> -->
      </geometry>
      <material name="white"/>
    </visual>
    <collision>
      <geometry>
        <cylinder length="0.0762" radius="0.1016"/>
      </geometry>
      <origin rpy="1.5707963267948966 0 0" xyz="0 0 0"/>
    </collision>
    <inertial>
      <mass value="0.01"/>
      <origin rpy="1.5707963267948966 0 0" xyz="0 0 0"/>
      <inertia ixx="1e-6" ixy="0" ixz="0" iyy="1e-6" iyz="0" izz="1e-6"/>
    </inertial>
  </link>
  <!-- ROBOT TOOLS -->
  <!-- <link name="claw_link">

      <collision>
        <origin xyz="0 0 0.0" rpy="0 0 0"/>
        <geometry>
          <box size="0.1 ${base_width + 0.23} ${base_height*3.3}"/>
        </geometry>
      </collision>

      <visual>
        <origin xyz="0 0.05 -0.34" rpy="0 0 ${-pi/2}"/>
        <geometry>
                                                            <box size="0.03 ${base_width + 0.23} ${base_height*2}"/>
          <mesh filename="package://nav/urdf/omniurdf/claw.stl" scale="0.15 0.1 0.07"/>
        </geometry>
        <material name="orange"/>
      </visual>

      <inertial>
        <mass value="0.1" />
        <origin xyz="0 0 0" rpy="0 0 0"/>
        <inertia ixx="1e-3" ixy="0" ixz="0" iyy="1e-3" iyz="0" izz="1e-3" />
      </inertial>
    </link>

    <joint type="fixed" name="claw_joint">
      <origin xyz="${base_length/2 + 0.15} 0 0" rpy="0 0 0"/>
      <child link="claw_link"/>
      <parent link="base_link"/>
    </joint> -->
  <!--~~~~~~~~~~~~~~~~~~~~~~~ ~ Sensors ~ ~~~~~~~~~~~~~~~~~~~~~~~~~~~~~-->
  <link name="camera">
    <visual name="camera_visual">
      <origin rpy=" 0 0 0" xyz="0 0 -0.05"/>
      <geometry>
        <box size=".03 .05 .10"/>
      </geometry>
      <material name="black"/>
    </visual>
  </link>
  <joint name="camera_joint" type="fixed">
    <origin rpy="0 0 0" xyz="0 0 0.1"/>
    <child link="camera"/>
    <parent link="base_link"/>
  </joint>
  <link name="range_front">
    <visual name="range_front_visual">
      <origin rpy="0 1.5707963267948966 0" xyz="0.01 0 0"/>
      <geometry>
        <cylinder length="0.03" radius="0.01"/>
      </geometry>
      <material name="green"/>
    </visual>
    <inertial>
      <origin rpy="0 0 0" xyz="0 0 0"/>
      <mass value="0.05"/>
      <inertia ixx="0.0007879166666666666" ixy="0.0" ixz="0.0" iyy="0.0007879166666666666" iyz="0.0" izz="0.0015625"/>
    </inertial>
  </link>
  <joint name="range_front_joint" type="fixed">
    <origin rpy="0 0 0" xyz="0.18415 0 0.03175"/>
    <child link="range_front"/>
    <parent link="base_link"/>
  </joint>
  <link name="range_rear">
    <visual name="range_rear_visual">
      <origin rpy="0 1.5707963267948966 0" xyz="0.01 0 0"/>
      <geometry>
        <cylinder length="0.03" radius="0.01"/>
      </geometry>
      <material name="green"/>
    </visual>
    <inertial>
      <origin rpy="0 0 0" xyz="0 0 0"/>
      <mass value="0.05"/>
      <inertia ixx="0.0007879166666666666" ixy="0.0" ixz="0.0" iyy="0.0007879166666666666" iyz="0.0" izz="0.0015625"/>
    </inertial>
  </link>
  <joint name="range_rear_joint" type="fixed">
    <origin rpy="0 0 3.141592653589793" xyz="-0.18415 0 0.03175"/>
    <child link="range_rear"/>
    <parent link="base_link"/>
  </joint>
  <link name="range_left">
    <visual name="range_left_visual">
      <origin rpy="0 1.5707963267948966 0" xyz="0.01 0 0"/>
      <geometry>
        <cylinder length="0.03" radius="0.01"/>
      </geometry>
      <material name="green"/>
    </visual>
    <inertial>
      <origin rpy="0 0 0" xyz="0 0 0"/>
      <mass value="0.05"/>
      <inertia ixx="0.0007879166666666666" ixy="0.0" ixz="0.0" iyy="0.0007879166666666666" iyz="0.0" izz="0.0015625"/>
    </inertial>
  </link>
  <joint name="range_left_joint" type="fixed">
    <origin rpy="0 0 1.5707963267948966" xyz="0 0.18415 0.03175"/>
    <child link="range_left"/>
    <parent link="base_link"/>
  </joint>
  <link name="range_right">
    <visual name="range_right_visual">
      <origin rpy="0 1.5707963267948966 0" xyz="0.01 0 0"/>
      <geometry>
        <cylinder length="0.03" radius="0.01"/>
      </geometry>
      <material name="green"/>
    </visual>
    <inertial>
      <origin rpy="0 0 0" xyz="0 0 0"/>
      <mass value="0.05"/>
      <inertia ixx="0.0007879166666666666" ixy="0.0" ixz="0.0" iyy="0.0007879166666666666" iyz="0.0" izz="0.0015625"/>
    </inertial>
  </link>
  <joint name="range_right_joint" type="fixed">
    <origin rpy="0 0 -1.5707963267948966" xyz="0 -0.18415 0.03175"/>
    <child link="range_right"/>
    <parent link="base_link"/>
  </joint>
  <!--~~~~~~~~~~~~~~~~~~~~~~~ ~ /Sensors ~ ~~~~~~~~~~~~~~~~~~~~~~~~~~~~~-->
  <joint name="fl_joint" type="continuous">
    <parent link="base_link"/>
    <child link="fl_link"/>
    <origin rpy="0 0 0" xyz="0.142875 0.23495 0.0"/>
    <axis xyz="0 1 0"/>
    <dynamics damping="1.0" friction="0.2" spring_stiffness="1"/>
    <limit effort="50" velocity="0.7"/>
  </joint>
  <transmission name="fl_joint_trans">
    <type>transmission_interface/SimpleTransmission</type>
    <joint name="fl_joint">
      <hardwareInterface>hardware_interface/VelocityJointInterface</hardwareInterface>
    </joint>
    <actuator name="fl_joint_wheel_motor">
      <hardwareInterface>hardware_interface/VelocityJointInterface</hardwareInterface>
      <mechanicalReduction>1</mechanicalReduction>
    </actuator>
  </transmission>
  <joint name="fr_joint" type="continuous">
    <parent link="base_link"/>
    <child link="fr_link"/>
    <origin rpy="0 0 0" xyz="0.142875 -0.23495 0.0"/>
    <axis xyz="0 1 0"/>
    <dynamics damping="1.0" friction="0.2" spring_stiffness="1"/>
    <limit effort="50" velocity="0.7"/>
  </joint>
  <transmission name="fr_joint_trans">
    <type>transmission_interface/SimpleTransmission</type>
    <joint name="fr_joint">
      <hardwareInterface>hardware_interface/VelocityJointInterface</hardwareInterface>
    </joint>
    <actuator name="fr_joint_wheel_motor">
      <hardwareInterface>hardware_interface/VelocityJointInterface</hardwareInterface>
      <mechanicalReduction>1</mechanicalReduction>
    </actuator>
  </transmission>
  <joint name="bl_joint" type="continuous">
    <parent link="base_link"/>
    <child link="bl_link"/>
    <origin rpy="0 0 0" xyz="-0.142875 0.23495 0.0"/>
    <axis xyz="0 1 0"/>
    <dynamics damping="1.0" friction="0.2" spring_stiffness="1"/>
    <limit effort="50" velocity="0.7"/>
  </joint>
  <transmission name="bl_joint_trans">
    <type>transmission_interface/SimpleTransmission</type>
    <joint name="bl_joint">
      <hardwareInterface>hardware_interface/VelocityJointInterface</hardwareInterface>
    </joint>
    <actuator name="bl_joint_wheel_motor">
      <hardwareInterface>hardware_interface/VelocityJointInterface</hardwareInterface>
      <mechanicalReduction>1</mechanicalReduction>
    </actuator>
  </transmission>
  <joint name="br_joint" type="continuous">
    <parent link="base_link"/>
    <child link="br_link"/>
    <origin rpy="0 0 0" xyz="-0.142875 -0.23495 0.0"/>
    <axis xyz="0 1 0"/>
    <dynamics damping="1.0" friction="0.2" spring_stiffness="1"/>
    <limit effort="50" velocity="0.7"/>
  </joint>
  <transmission name="br_joint_trans">
    <type>transmission_interface/SimpleTransmission</type>
    <joint name="br_joint">
      <hardwareInterface>hardware_interface/VelocityJointInterface</hardwareInterface>
    </joint>
    <actuator name="br_joint_wheel_motor">
      <hardwareInterface>hardware_interface/VelocityJointInterface</hardwareInterface>
      <mechanicalReduction>1</mechanicalReduction>
    </actuator>
  </transmission>
</robot>

