<?xml version="1.0"?>
<robot name="robot" xmlns:xacro="http://www.ros.org/wiki/xacro">

	<xacro:include filename="$(find my_robot_model)/urdf/materials.xacro" />
	<xacro:property name="side" value="left" />
	<!-- <xacro:macro name= "wheel" side="left" x="0.25" y="0.4" z="1.0" /> -->
	<mesh filename="package://my_robot_model/models/base_frame.stl" scale="1.0 1.0 1.0"/>

	<link name="base_link">

		<origin xyz="0.0 0.0 0.0" rpy="0 0.0 0.0" />

		<visual name="base_visual">

			<geometry>
				<box size="0.2 0.2 0.1" />
			</geometry>

			<material name="blue" />

		</visual>


		<inertial>

			<mass value="1" />
			<inertia ixx="100" ixy="0" ixz="0" iyy="100" iyz="0" izz="100" />

		</inertial>

		<collision>

			<geometry>
				<box size="0.2 0.6 0.6" />
			</geometry>

		</collision>


	</link>

	<link name="wheel_${side}">
		<origin xyz="0.2 0 0" rpy=" 0 0 0" />

		<visual name="wheel_${side}_visual">

			<geometry>
				<cylinder length="0.05" radius="0.1" />
			</geometry>

			<material name="red" />

		</visual>

		<inertial>

			<mass value="1" />
			<inertia ixx="100" ixy="0" ixz="0" iyy="100" iyz="0" izz="100" />

		</inertial>

		<collision>

			<geometry>
				<cylinder length="0.05" radius="0.1" />
			</geometry>

		</collision>

	</link>

	<link name="wheel_right">

		<origin xyz="-2.2 0 0" rpy="0 1.57 0" />

		<visual name="wheel_left_visual">

			<geometry>

				<cylinder length="0.05" radius="0.1" />

			</geometry>

			<material name="white" />

		</visual>

		<inertial>

			<mass value="1" />
			<inertia ixx="100" ixy="0" ixz="0" iyy="100" iyz="0" izz="100" />

		</inertial>

		<collision>

			<geometry>
				<cylinder length="0.05" radius="0.1" />
			</geometry>

		</collision>

	</link>

	<joint type="continuous" name="left_wheel_joint">

		<axis xyz="0 0 1" />
		<origin xyz="0.15 0.0 0" rpy="0 1.57 0" />
		<child link="wheel_left" />
		<parent link="base_link" />

	</joint>

	<joint type="continuous" name="right_wheel_joint">

		<axis xyz="0 0 1" />
		<origin xyz="-0.15 0.0 0" rpy="0 1.57 0" />
		<child link="wheel_right" />
		<parent link="base_link" />

	</joint>
</robot>