<?xml version="1.0"?>
<robot name="robot" xmlns:xacro="http://www.ros.org/wiki/xacro">

	<link name="base_link">

		<origin xyz="0.0 0.0 0.0" rpy="0 0.0 0.0" />

		<visual name="base_visual">

			<geometry>
				<box size="0.2 0.2 0.1" />
			</geometry>

			<material name="">
				<color rgb="1.0 0.0 0.0"></color>
			</material>

		</visual>


		<inertial>

			<mass value="1" />
			<inertia ixx="100" ixy="0" ixz="0" iyy="100" iyz="0" izz="100" />

		</inertial>

		<collision>

			<geometry>
				<box size="0.2 0.6 0.6" />
			</geometry>

		</collision>


	</link>

	<link name="wheel_left">
		<origin xyz="0.2 0 0" rpy=" 0 0 0" />

		<visual name="wheel_left_visual">

			<geometry>
				<cylinder length="0.05" radius="0.1" />
			</geometry>

			<material name="">
				<color rgb="1.0 0.0 0.0"></color>
			</material>

		</visual>

		<inertial>

			<mass value="1" />
			<inertia ixx="100" ixy="0" ixz="0" iyy="100" iyz="0" izz="100" />

		</inertial>

		<collision>

			<geometry>
				<cylinder length="0.05" radius="0.1" />
			</geometry>

		</collision>

	</link>

	<link name="wheel_right">

		<origin xyz="-2.2 0 0" rpy="0 1.57 0" />

		<visual name="wheel_left_visual">

			<geometry>

				<cylinder length="0.05" radius="0.1" />

			</geometry>

			<material name="">
				<color rgb="1.0 0.0 0.0"></color>
			</material>

		</visual>

		<inertial>

			<mass value="1" />
			<inertia ixx="100" ixy="0" ixz="0" iyy="100" iyz="0" izz="100" />

		</inertial>

		<collision>

			<geometry>
				<cylinder length="0.05" radius="0.1" />
			</geometry>

		</collision>

	</link>

	<joint type="continuous" name="left_wheel_joint">

		<axis xyz = "0 0 1"/>
		<origin xyz="0.15 0.0 0" rpy="0 1.57 0" />
		<child link="wheel_left" />
		<parent link="base_link" />

	</joint>

	<joint type="continuous" name="right_wheel_joint">

		<axis xyz = "0 0 1"/>
		<origin xyz="-0.15 0.0 0" rpy="0 1.57 0" />
		<child link="wheel_right" />
		<parent link="base_link" />

	</joint>

</robot>