<xacro:macro name="wheel" params="side x y z" xmlns:xacro="http://www.ros.org/wiki/xacro">

    <link name='wheel_${side}'>
        <visual name='wheel_${side}_visual'>

            <origin xyz="0.2 0 0" rpy=" 1.5 0.0 1.5" />
            <geometry>
                <cylinder length="0.1" radius="0.1" />
            </geometry>
            <material name="red" />

        </visual>
    </link>

    <joint name="wheel_${side}_joint" type="continuous">

        <origin xyz="${x} ${y} ${z}" rpy="0 0 0" />
        <child link="wheel_${side}" />
        <parent link="base_link" />

    </joint>

</xacro:macro>
